{
 "cells": [
  {
   "cell_type": "code",
   "execution_count": 1,
   "metadata": {},
   "outputs": [],
   "source": [
    "import boto3\n",
    "\n",
    "identitystore = boto3.client('identitystore')\n"
   ]
  },
  {
   "cell_type": "code",
   "execution_count": 5,
   "metadata": {},
   "outputs": [
    {
     "ename": "ResourceNotFoundException",
     "evalue": "An error occurred (ResourceNotFoundException) when calling the ListUsers operation: IdentityStore not present for IdentityStoreId: d-9f6708e41b",
     "output_type": "error",
     "traceback": [
      "\u001b[31m---------------------------------------------------------------------------\u001b[39m",
      "\u001b[31mResourceNotFoundException\u001b[39m                 Traceback (most recent call last)",
      "\u001b[36mCell\u001b[39m\u001b[36m \u001b[39m\u001b[32mIn[5]\u001b[39m\u001b[32m, line 1\u001b[39m\n\u001b[32m----> \u001b[39m\u001b[32m1\u001b[39m response = \u001b[43midentitystore\u001b[49m\u001b[43m.\u001b[49m\u001b[43mlist_users\u001b[49m\u001b[43m(\u001b[49m\n\u001b[32m      2\u001b[39m \u001b[43m    \u001b[49m\u001b[43mIdentityStoreId\u001b[49m\u001b[43m=\u001b[49m\u001b[33;43m'\u001b[39;49m\u001b[33;43md-9f6708e41b\u001b[39;49m\u001b[33;43m'\u001b[39;49m\u001b[43m  \u001b[49m\u001b[38;5;66;43;03m# You need to find this from the console or SSO setup\u001b[39;49;00m\n\u001b[32m      3\u001b[39m \u001b[43m)\u001b[49m\n",
      "\u001b[36mFile \u001b[39m\u001b[32m~/cloudtrail-project/.venv/lib/python3.11/site-packages/botocore/client.py:570\u001b[39m, in \u001b[36mClientCreator._create_api_method.<locals>._api_call\u001b[39m\u001b[34m(self, *args, **kwargs)\u001b[39m\n\u001b[32m    566\u001b[39m     \u001b[38;5;28;01mraise\u001b[39;00m \u001b[38;5;167;01mTypeError\u001b[39;00m(\n\u001b[32m    567\u001b[39m         \u001b[33mf\u001b[39m\u001b[33m\"\u001b[39m\u001b[38;5;132;01m{\u001b[39;00mpy_operation_name\u001b[38;5;132;01m}\u001b[39;00m\u001b[33m() only accepts keyword arguments.\u001b[39m\u001b[33m\"\u001b[39m\n\u001b[32m    568\u001b[39m     )\n\u001b[32m    569\u001b[39m \u001b[38;5;66;03m# The \"self\" in this scope is referring to the BaseClient.\u001b[39;00m\n\u001b[32m--> \u001b[39m\u001b[32m570\u001b[39m \u001b[38;5;28;01mreturn\u001b[39;00m \u001b[38;5;28;43mself\u001b[39;49m\u001b[43m.\u001b[49m\u001b[43m_make_api_call\u001b[49m\u001b[43m(\u001b[49m\u001b[43moperation_name\u001b[49m\u001b[43m,\u001b[49m\u001b[43m \u001b[49m\u001b[43mkwargs\u001b[49m\u001b[43m)\u001b[49m\n",
      "\u001b[36mFile \u001b[39m\u001b[32m~/cloudtrail-project/.venv/lib/python3.11/site-packages/botocore/context.py:123\u001b[39m, in \u001b[36mwith_current_context.<locals>.decorator.<locals>.wrapper\u001b[39m\u001b[34m(*args, **kwargs)\u001b[39m\n\u001b[32m    121\u001b[39m \u001b[38;5;28;01mif\u001b[39;00m hook:\n\u001b[32m    122\u001b[39m     hook()\n\u001b[32m--> \u001b[39m\u001b[32m123\u001b[39m \u001b[38;5;28;01mreturn\u001b[39;00m \u001b[43mfunc\u001b[49m\u001b[43m(\u001b[49m\u001b[43m*\u001b[49m\u001b[43margs\u001b[49m\u001b[43m,\u001b[49m\u001b[43m \u001b[49m\u001b[43m*\u001b[49m\u001b[43m*\u001b[49m\u001b[43mkwargs\u001b[49m\u001b[43m)\u001b[49m\n",
      "\u001b[36mFile \u001b[39m\u001b[32m~/cloudtrail-project/.venv/lib/python3.11/site-packages/botocore/client.py:1031\u001b[39m, in \u001b[36mBaseClient._make_api_call\u001b[39m\u001b[34m(self, operation_name, api_params)\u001b[39m\n\u001b[32m   1027\u001b[39m     error_code = error_info.get(\u001b[33m\"\u001b[39m\u001b[33mQueryErrorCode\u001b[39m\u001b[33m\"\u001b[39m) \u001b[38;5;129;01mor\u001b[39;00m error_info.get(\n\u001b[32m   1028\u001b[39m         \u001b[33m\"\u001b[39m\u001b[33mCode\u001b[39m\u001b[33m\"\u001b[39m\n\u001b[32m   1029\u001b[39m     )\n\u001b[32m   1030\u001b[39m     error_class = \u001b[38;5;28mself\u001b[39m.exceptions.from_code(error_code)\n\u001b[32m-> \u001b[39m\u001b[32m1031\u001b[39m     \u001b[38;5;28;01mraise\u001b[39;00m error_class(parsed_response, operation_name)\n\u001b[32m   1032\u001b[39m \u001b[38;5;28;01melse\u001b[39;00m:\n\u001b[32m   1033\u001b[39m     \u001b[38;5;28;01mreturn\u001b[39;00m parsed_response\n",
      "\u001b[31mResourceNotFoundException\u001b[39m: An error occurred (ResourceNotFoundException) when calling the ListUsers operation: IdentityStore not present for IdentityStoreId: d-9f6708e41b"
     ]
    }
   ],
   "source": [
    "response = identitystore.list_users(\n",
    "    IdentityStoreId='d-9f6708e41b'  # You need to find this from the console or SSO setup\n",
    ")"
   ]
  },
  {
   "cell_type": "code",
   "execution_count": null,
   "metadata": {},
   "outputs": [],
   "source": []
  }
 ],
 "metadata": {
  "kernelspec": {
   "display_name": ".venv",
   "language": "python",
   "name": "python3"
  },
  "language_info": {
   "codemirror_mode": {
    "name": "ipython",
    "version": 3
   },
   "file_extension": ".py",
   "mimetype": "text/x-python",
   "name": "python",
   "nbconvert_exporter": "python",
   "pygments_lexer": "ipython3",
   "version": "3.11.0"
  }
 },
 "nbformat": 4,
 "nbformat_minor": 2
}
